Traceback (most recent call last):
  File "/home/pengyu/.local/lib/python3.9/site-packages/jupyter_cache/executors/utils.py", line 58, in single_nb_execution
    executenb(
  File "/software/python-anaconda-2022.05-el8-x86_64/lib/python3.9/site-packages/nbclient/client.py", line 1204, in execute
    return NotebookClient(nb=nb, resources=resources, km=km, **kwargs).execute()
  File "/software/python-anaconda-2022.05-el8-x86_64/lib/python3.9/site-packages/nbclient/util.py", line 84, in wrapped
    return just_run(coro(*args, **kwargs))
  File "/software/python-anaconda-2022.05-el8-x86_64/lib/python3.9/site-packages/nbclient/util.py", line 62, in just_run
    return loop.run_until_complete(coro)
  File "/software/python-anaconda-2022.05-el8-x86_64/lib/python3.9/asyncio/base_events.py", line 647, in run_until_complete
    return future.result()
  File "/software/python-anaconda-2022.05-el8-x86_64/lib/python3.9/site-packages/nbclient/client.py", line 663, in async_execute
    await self.async_execute_cell(
  File "/software/python-anaconda-2022.05-el8-x86_64/lib/python3.9/site-packages/nbclient/client.py", line 965, in async_execute_cell
    await self._check_raise_for_error(cell, cell_index, exec_reply)
  File "/software/python-anaconda-2022.05-el8-x86_64/lib/python3.9/site-packages/nbclient/client.py", line 862, in _check_raise_for_error
    raise CellExecutionError.from_cell_and_msg(cell, exec_reply_content)
nbclient.exceptions.CellExecutionError: An error occurred while executing the following cell:
------------------
#Site Data
df = pd.read_csv("data/calibration_globalModel.csv") # dataset
df = df.sort_values(by=['theta_global'])
z0_list = df['z_1995_global'].to_numpy() # initial distribution of agriculture
Î³_list  = np.array([583.5109738331764]) #  distribution of gammas (aka impact of cutting down forests)
x0_list = df['x_1995_global'].to_numpy() # initial distribution of carbon absoprtion of the amazon
Î¸_list  = np.array([1.5200911027301107]) #  distribution of the productivity parameters

Z0_list = z0_list/ normalization
X0_list = x0_list/ normalization

zÌ„ = (df['zbar_2017_global'].to_numpy() )/normalization # distribution of the upper bound of agriculture in each site
n = len(zÌ„) # total number of sites 
------------------

[0;31m---------------------------------------------------------------------------[0m
[0;31mKeyError[0m                                  Traceback (most recent call last)
File [0;32m~/.local/lib/python3.9/site-packages/pandas/core/indexes/base.py:3790[0m, in [0;36mIndex.get_loc[0;34m(self, key)[0m
[1;32m   3789[0m [38;5;28;01mtry[39;00m:
[0;32m-> 3790[0m     [38;5;28;01mreturn[39;00m [38;5;28;43mself[39;49m[38;5;241;43m.[39;49m[43m_engine[49m[38;5;241;43m.[39;49m[43mget_loc[49m[43m([49m[43mcasted_key[49m[43m)[49m
[1;32m   3791[0m [38;5;28;01mexcept[39;00m [38;5;167;01mKeyError[39;00m [38;5;28;01mas[39;00m err:

File [0;32mindex.pyx:152[0m, in [0;36mpandas._libs.index.IndexEngine.get_loc[0;34m()[0m

File [0;32mindex.pyx:181[0m, in [0;36mpandas._libs.index.IndexEngine.get_loc[0;34m()[0m

File [0;32mpandas/_libs/hashtable_class_helper.pxi:7080[0m, in [0;36mpandas._libs.hashtable.PyObjectHashTable.get_item[0;34m()[0m

File [0;32mpandas/_libs/hashtable_class_helper.pxi:7088[0m, in [0;36mpandas._libs.hashtable.PyObjectHashTable.get_item[0;34m()[0m

[0;31mKeyError[0m: 'z_1995_global'

The above exception was the direct cause of the following exception:

[0;31mKeyError[0m                                  Traceback (most recent call last)
Input [0;32mIn [3][0m, in [0;36m<cell line: 4>[0;34m()[0m
[1;32m      2[0m df [38;5;241m=[39m pd[38;5;241m.[39mread_csv([38;5;124m"[39m[38;5;124mdata/calibration_globalModel.csv[39m[38;5;124m"[39m) [38;5;66;03m# dataset[39;00m
[1;32m      3[0m df [38;5;241m=[39m df[38;5;241m.[39msort_values(by[38;5;241m=[39m[[38;5;124m'[39m[38;5;124mtheta_global[39m[38;5;124m'[39m])
[0;32m----> 4[0m z0_list [38;5;241m=[39m [43mdf[49m[43m[[49m[38;5;124;43m'[39;49m[38;5;124;43mz_1995_global[39;49m[38;5;124;43m'[39;49m[43m][49m[38;5;241m.[39mto_numpy() [38;5;66;03m# initial distribution of agriculture[39;00m
[1;32m      5[0m Î³_list  [38;5;241m=[39m np[38;5;241m.[39marray([[38;5;241m583.5109738331764[39m]) [38;5;66;03m#  distribution of gammas (aka impact of cutting down forests)[39;00m
[1;32m      6[0m x0_list [38;5;241m=[39m df[[38;5;124m'[39m[38;5;124mx_1995_global[39m[38;5;124m'[39m][38;5;241m.[39mto_numpy() [38;5;66;03m# initial distribution of carbon absoprtion of the amazon[39;00m

File [0;32m~/.local/lib/python3.9/site-packages/pandas/core/frame.py:3896[0m, in [0;36mDataFrame.__getitem__[0;34m(self, key)[0m
[1;32m   3894[0m [38;5;28;01mif[39;00m [38;5;28mself[39m[38;5;241m.[39mcolumns[38;5;241m.[39mnlevels [38;5;241m>[39m [38;5;241m1[39m:
[1;32m   3895[0m     [38;5;28;01mreturn[39;00m [38;5;28mself[39m[38;5;241m.[39m_getitem_multilevel(key)
[0;32m-> 3896[0m indexer [38;5;241m=[39m [38;5;28;43mself[39;49m[38;5;241;43m.[39;49m[43mcolumns[49m[38;5;241;43m.[39;49m[43mget_loc[49m[43m([49m[43mkey[49m[43m)[49m
[1;32m   3897[0m [38;5;28;01mif[39;00m is_integer(indexer):
[1;32m   3898[0m     indexer [38;5;241m=[39m [indexer]

File [0;32m~/.local/lib/python3.9/site-packages/pandas/core/indexes/base.py:3797[0m, in [0;36mIndex.get_loc[0;34m(self, key)[0m
[1;32m   3792[0m     [38;5;28;01mif[39;00m [38;5;28misinstance[39m(casted_key, [38;5;28mslice[39m) [38;5;129;01mor[39;00m (
[1;32m   3793[0m         [38;5;28misinstance[39m(casted_key, abc[38;5;241m.[39mIterable)
[1;32m   3794[0m         [38;5;129;01mand[39;00m [38;5;28many[39m([38;5;28misinstance[39m(x, [38;5;28mslice[39m) [38;5;28;01mfor[39;00m x [38;5;129;01min[39;00m casted_key)
[1;32m   3795[0m     ):
[1;32m   3796[0m         [38;5;28;01mraise[39;00m InvalidIndexError(key)
[0;32m-> 3797[0m     [38;5;28;01mraise[39;00m [38;5;167;01mKeyError[39;00m(key) [38;5;28;01mfrom[39;00m [38;5;21;01merr[39;00m
[1;32m   3798[0m [38;5;28;01mexcept[39;00m [38;5;167;01mTypeError[39;00m:
[1;32m   3799[0m     [38;5;66;03m# If we have a listlike key, _check_indexing_error will raise[39;00m
[1;32m   3800[0m     [38;5;66;03m#  InvalidIndexError. Otherwise we fall through and re-raise[39;00m
[1;32m   3801[0m     [38;5;66;03m#  the TypeError.[39;00m
[1;32m   3802[0m     [38;5;28mself[39m[38;5;241m.[39m_check_indexing_error(key)

[0;31mKeyError[0m: 'z_1995_global'
KeyError: 'z_1995_global'

